Workbook

Sheet 説明
B2: Kanade — 日本市場 財務モデル
B3: AI 音楽 × 店舗向け BGM サブスクリプション事業の収益シミュレーション
B5: 使い方
B6: 編集するのはここだけ | C6: 「前提条件」シートの青字セル（黄色背景）のみ。他はすべて数式で自動計算される。
B7: 結果を見る場所 | C7: 「単位経済」= 1 店舗あたりの採算 / 「損益分岐点」= 何店舗で黒字化するか / 「月次予測」= 36ヶ月の推移
B8: 色の意味 | C8: 青字 = 手入力の前提値 ・ 黒字 = 数式 ・ 緑字 = 他シート参照
B9: 通貨 | C9: すべて日本円。インフラ費のみ米ドル建てを為替レートで換算。
B11: シート構成
B12: 前提条件 | C12: 全パラメータ。ここを変えるとモデル全体が再計算される。
B13: 単位経済 | C13: 1 店舗あたりの月次貢献利益、LTV、CAC 回収期間。
B14: 月次予測 | C14: 36ヶ月の店舗数・売上・費用・営業利益の推移。
B15: 損益分岐点 | C15: 黒字化に必要な店舗数と、価格 × 分配率 / 解約率 × CAC の感応度分析。
B16: 競合比較 | C16: USEN・OTORAKU 等との価格比較（2026年8月時点の調査値）。
B18: 重要な前提
C19: ・純売上 = 税込売上 − 消費税 − Stripe 手数料。分配プールはこの「純売上」に対して 45%（設計書 08 と同じ定義）。
C20: ・つまり税込売上のうち手元に残る貢献利益は約 48%。この構造が損益分岐点を大きく左右する。
C21: ・創作者への分配は商用再生のみが対象。リスナー向け無料ストリーミングは分配対象外。
C22: ・インフラ費は R2（エグレス無料）前提。帯域費をゼロとしているのはこのため。
C23: ・人件費は日本の相場を仮置きしたもの。実際の採用計画に合わせて必ず調整すること。
B25: 出典
C26: ・JASRAC BGM 使用料（500㎡以下 年額 ¥6,000 ほか面積区分）: JASRAC 公式 FAQ / 使用料規程 第12節 BGM
C27: ・USEN MUSIC 月額 ¥6,600〜・初期費用 ¥22,000〜33,000: USEN 公式および代理店公開情報（2026年8月時点）
C28: ・モンスター・チャンネル ¥1,880〜2,880（税抜）: monstar.ch 公式料金ページ（2026年8月時点）
C29: ・その他 BGM サービス料金: 店舗BGMサービス比較記事（2026年版）
C30: ・レコード演奏・伝達権: 2026年6月17日成立・6月24日公布、施行は公布から3年以内
C31: ・Stripe 手数料率 3.6%（日本国内カード）: Stripe 公開価格
C32: ・上記以外の数値（成長率・解約率・CAC・人件費）は仮置き。実測値で置き換えること。
C34: 本モデルは事業計画の検討用であり、会計・税務・法務上の助言ではありません。

Sheet 前提条件
B2: 前提条件
B3: 青字・黄色背景のセルのみ編集する。D〜F列は参考値（モデルは C 列のみを読む）。
B5: 項目 | C5: 現在値 | D5: 保守 | E5: 基本 | F5: 楽観 | G5: 備考
B6: A. 価格（税込）
B7: Standard 月額 | C7: 1980 | D7: 1480 | E7: 1980 | F7: 2980 | G7: 設計書 01 の想定価格
B8: Custom 月額 | C8: 4980 | D8: 3980 | E8: 4980 | F8: 6980 | G8: 店舗専属カタログ・多店舗管理
B9: 年払い割引率 | C9: 0.2 | D9: 0.2 | E9: 0.2 | F9: 0.15 | G9: 年払い顧客に適用
B10: 年払い顧客比率 | C10: 0.3 | D10: 0.15 | E10: 0.3 | F10: 0.5 | G10: 高いほど解約率が下がるが売上は減る
B12: B. 顧客構成
B13: Standard 比率 | C13: 0.85 | D13: 0.92 | E13: 0.85 | F13: 0.75 | G13: 残りが Custom
B15: C. 収益構造
B16: 消費税率 | C16: 0.1 | D16: 0.1 | E16: 0.1 | F16: 0.1 | G16: 総額表示のため税込価格から控除
B17: Stripe 手数料率 | C17: 0.036 | D17: 0.036 | E17: 0.036 | F17: 0.036 | G17: 日本国内カード。税込金額に対して課金
B18: 創作者分配プール率 | C18: 0.45 | D18: 0.45 | E18: 0.45 | F18: 0.3 | G18: 純売上に対する比率（設計書 08）
B20: D. 成長と解約
B21: 初月の新規獲得店舗数 | C21: 5 | D21: 3 | E21: 5 | F21: 10 | G21: Phase 2 開始時点
B22: 新規獲得の月次成長率 | C22: 0.15 | D22: 0.08 | E22: 0.15 | F22: 0.25 | G22: 営業体制の拡大ペース
B23: 月次新規獲得の上限 | C23: 120 | D23: 60 | E23: 120 | F23: 250 | G23: 営業キャパシティの天井
B24: 月次解約率 | C24: 0.03 | D24: 0.05 | E24: 0.03 | F24: 0.02 | G24: 設計書 09 の目標は 3% 未満
B26: E. 顧客獲得コスト
B27: CAC（1 店舗あたり） | C27: 20000 | D27: 35000 | E27: 20000 | F27: 10000 | G27: 広告・インサイドセールス・代理店手数料の合計
B29: F. 固定費（月額）
B30: エンジニア人数 | C30: 2 | D30: 3 | E30: 2 | F30: 2
B31: エンジニア給与（1名） | C31: 700000 | D31: 700000 | E31: 700000 | F31: 700000 | G31: 社会保険料等を含む会社負担額
B32: 審査担当人数 | C32: 1 | D32: 2 | E32: 1 | F32: 1 | G32: カタログ汚染防止の要。曲数に比例して増える
B33: 審査担当給与（1名） | C33: 300000 | D33: 300000 | E33: 300000 | F33: 300000
B34: カスタマーサポート人数 | C34: 1 | D34: 2 | E34: 1 | F34: 1
B35: サポート給与（1名） | C35: 300000 | D35: 300000 | E35: 300000 | F35: 300000
B36: 営業人数 | C36: 1 | D36: 2 | E36: 1 | F36: 1
B37: 営業給与（1名） | C37: 400000 | D37: 400000 | E37: 400000 | F37: 400000 | G37: 固定給。歩合は CAC に含む
B38: その他固定費 | C38: 200000 | D38: 300000 | E38: 200000 | F38: 150000 | G38: オフィス・SaaS・会計
B39: 法務費（月次按分） | C39: 50000 | D39: 80000 | E39: 50000 | F39: 30000 | G39: 初期の弁護士費用 ¥30〜100万を按分＋継続顧問料
B41: G. インフラ
B42: 為替レート（JPY/USD） | C42: 155 | D42: 165 | E42: 155 | F42: 145
B43: ストレージ単価（USD/GB/月） | C43: 0.015 | D43: 0.015 | E43: 0.015 | F43: 0.015 | G43: Cloudflare R2。エグレス（帯域）は無料
B44: 1 曲あたり容量（GB） | C44: 0.042 | D44: 0.042 | E44: 0.042 | F44: 0.042 | G44: 原音源 30MB ＋ 変換後 12MB
B45: 初期カタログ曲数 | C45: 3000 | D45: 3000 | E45: 3000 | F45: 3000 | G45: Phase 1 の完了条件
B46: 月間追加曲数 | C46: 2000 | D46: 1000 | E46: 2000 | F46: 4000 | G46: 創作者の供給ペース
B47: 固定インフラ費（USD/月） | C47: 140 | D47: 140 | E47: 140 | F47: 140 | G47: Postgres・Meilisearch・ClickHouse
B48: 変換費（USD/1000曲） | C48: 8 | D48: 8 | E48: 8 | F48: 8 | G48: ffmpeg スポットインスタンス
...

Sheet 単位経済
B2: 単位経済（1 店舗あたり・月次）
B3: 税込価格から消費税と決済手数料を引き、残りの 45% を創作者に分配した後の手取り。
B5: 項目 | C5: Standard | D5: Custom | E5: 加重平均 | F5: 計算の説明
B6: 表示価格（税込） | C6: =前提条件!$C$7 -> 1980 | D6: =前提条件!$C$8 -> 4980 | E6: =C6*前提条件!$C$13+D6*(1-前提条件!$C$13) -> 2430 | F6: 前提条件 A より
B7: 実効単価（年払い割引後・税込） | C7: =前提条件!$C$7*(1-前提条件!$C$10*前提条件!$C$9) -> 1861.2 | D7: =前提条件!$C$8*(1-前提条件!$C$10*前提条件!$C$9) -> 4681.2 | E7: =C7*前提条件!$C$13+D7*(1-前提条件!$C$13) -> 2284.2 | F7: 年払い顧客比率 × 割引率の分だけ低下
B8: 消費税控除後（税抜売上） | C8: =C7/(1+前提条件!$C$16) -> 1692 | D8: =D7/(1+前提条件!$C$16) -> 4255.6364 | E8: =E7/(1+前提条件!$C$16) -> 2076.5455 | F8: 総額表示のため税込単価から割り戻す
B9: Stripe 手数料 | C9: =-C7*前提条件!$C$17 -> -67.0032 | D9: =-D7*前提条件!$C$17 -> -168.5232 | E9: =-E7*前提条件!$C$17 -> -82.2312 | F9: 税込金額に対して課金される
B10: 純売上 | C10: =C8+C9 -> 1624.9968 | D10: =D8+D9 -> 4087.1132 | E10: =E8+E9 -> 1994.3143 | F10: 分配プールの計算基礎（設計書 08 の定義）
B11: 創作者分配プール | C11: =-C10*前提条件!$C$18 -> -731.24856 | D11: =-D10*前提条件!$C$18 -> -1839.2009 | E11: =-E10*前提条件!$C$18 -> -897.44141 | F11: 純売上 × 分配率
B12: 貢献利益（1 店舗・月） | C12: =C10+C11 -> 893.74824 | D12: =D10+D11 -> 2247.9122 | E12: =E10+E11 -> 1096.8728 | F12: 固定費を回収する原資
B13: 貢献利益率（対 表示価格） | C13: =C12/C6 -> 0.451388 | D13: =D12/D6 -> 0.451388 | E13: =E12/E6 -> 0.451388 | F13: 税込売上のうち手元に残る割合。50% を切る点が本モデル最大の制約
B15: 顧客生涯価値
B16: 平均継続月数 | C16: =1/前提条件!$C$24 -> 33.333333 | D16: =1/前提条件!$C$24 -> 33.333333 | E16: =1/前提条件!$C$24 -> 33.333333 | F16: 1 ÷ 月次解約率
B17: LTV（貢献利益ベース） | C17: =C12*C16 -> 29791.608 | D17: =D12*D16 -> 74930.408 | E17: =E12*E16 -> 36562.428 | F17: 分配プール控除後の貢献利益で算出（売上ベースではない）
B18: CAC | C18: =前提条件!$C$27 -> 20000 | D18: =前提条件!$C$27 -> 20000 | E18: =前提条件!$C$27 -> 20000 | F18: 前提条件 E より
B19: LTV / CAC | C19: =C17/C18 -> 1.4895804 | D19: =D17/D18 -> 3.7465204 | E19: =E17/E18 -> 1.8281214 | F19: 健全水準は 3.0x 以上。下回る場合は価格・解約率・CAC のいずれかを改善する
B20: CAC 回収期間（月） | C20: =C18/C12 -> 22.377666 | D20: =D18/D12 -> 8.8971445 | E20: =E18/E12 -> 18.233654 | F20: 12ヶ月以内が目安
B22: 判定 | C22: =IF(E19>=3,"健全","要改善") -> 要改善 | F22: LTV/CAC が 3.0x 未満のとき「要改善」。損益分岐点シートの感応度表で改善余地を確認する。
B24: 参考：JASRAC BGM 使用料（店舗が現在負担している著作権料）
B25: 店舗面積 | C25: 年額（税別） | D25: 月換算
B26: 500㎡以下 | C26: 6000 | D26: =C26/12 -> 500
B27: 1,000㎡以下 | C27: 10000 | D27: =C27/12 -> 833.33333
B28: 3,000㎡以下 | C28: 20000 | D28: =C28/12 -> 1666.6667
B29: 6,000㎡以下 | C29: 30000 | D29: =C29/12 -> 2500
B30: 9,000㎡以下 | C30: 40000 | D30: =C30/12 -> 3333.3333
B31: 9,000㎡超 | C31: 50000 | D31: =C31/12 -> 4166.6667
B32: 出典: JASRAC 公式 FAQ・使用料規程 第12節 BGM
B33: 小規模店舗では月換算 ¥500 程度にすぎず、「JASRAC 節約」は訴求点にならない。

Sheet 月次予測
B2: 36ヶ月 月次予測
B3: 前提条件シートの数値をすべて参照。数字を変えると全期間が再計算される。
B5: 月 | C5: 1 | D5: 2 | E5: 3 | F5: 4 | G5: 5 | H5: 6 | I5: 7 | J5: 8 | K5: 9 | L5: 10 | M5: 11 | N5: 12 | O5: 13 | P5: 14 | Q5: 15 | R5: 16 | S5: 17 | T5: 18 | U5: 19 | V5: 20 | W5: 21 | X5: 22 | Y5: 23 | Z5: 24 | AA5: 25 | AB5: 26 | AC5: 27 | AD5: 28 | AE5: 29 | AF5: 30 | AG5: 31 | AH5: 32 | AI5: 33 | AJ5: 34 | AK5: 35 | AL5: 36
B6: 店舗数
B7: 期首店舗数 | C7: 0 | D7: =C10 -> 5 | E7: =D10 -> 11 | F7: =E10 -> 18 | G7: =F10 -> 25 | H7: =G10 -> 33 | I7: =H10 -> 42 | J7: =I10 -> 53 | K7: =J10 -> 64 | ... AL7: =AK10 -> 1696
B8: 新規獲得 | C8: =MIN(前提条件!$C$23,ROUND(前提条件!$C$21*(1+前提条件!$C$22)^0,0)) -> 5 | D8: =MIN(前提条件!$C$23,ROUND(前提条件!$C$21*(1+前提条件!$C$22)^1,0)) -> 6 | E8: =MIN(前提条件!$C$23,ROUND(前提条件!$C$21*(1+前提条件!$C$22)^2,0)) -> 7 | F8: =MIN(前提条件!$C$23,ROUND(前提条件!$C$21*(1+前提条件!$C$22)^3,0)) -> 8 | G8: =MIN(前提条件!$C$23,ROUND(前提条件!$C$21*(1+前提条件!$C$22)^4,0)) -> 9 | H8: =MIN(前提条件!$C$23,ROUND(前提条件!$C$21*(1+前提条件!$C$22)^5,0)) -> 10 | I8: =MIN(前提条件!$C$23,ROUND(前提条件!$C$21*(1+前提条件!$C$22)^6,0)) -> 12 | J8: =MIN(前提条件!$C$23,ROUND(前提条件!$C$21*(1+前提条件!$C$22)^7,0)) -> 13 | K8: =MIN(前提条件!$C$23,ROUND(前提条件!$C$21*(1+前提条件!$C$22)^8,0)) -> 15 | L8: =MIN(前提条件!$C$23,ROUND(前提条件!$C$21*(1+前提条件!$C$22)^9,0)) -> 18 | M8: =MIN(前提条件!$C$23,ROUND(前提条件!$C$21*(1+前提条件!$C$22)^10,0)) -> 20 | N8: =MIN(前提条件!$C$23,ROUND(前提条件!$C$21*(1+前提条件!$C$22)^11,0)) -> 23 | O8: =MIN(前提条件!$C$23,ROUND(前提条件!$C$21*(1+前提条件!$C$22)^12,0)) -> 27 | P8: =MIN(前提条件!$C$23,ROUND(前提条件!$C$21*(1+前提条件!$C$22)^13,0)) -> 31 | Q8: =MIN(前提条件!$C$23,ROUND(前提条件!$C$21*(1+前提条件!$C$22)^14,0)) -> 35 | R8: =MIN(前提条件!$C$23,ROUND(前提条件!$C$21*(1+前提条件!$C$22)^15,0)) -> 41 | S8: =MIN(前提条件!$C$23,ROUND(前提条件!$C$21*(1+前提条件!$C$22)^16,0)) -> 47 | T8: =MIN(前提条件!$C$23,ROUND(前提条件!$C$21*(1+前提条件!$C$22)^17,0)) -> 54 | U8: =MIN(前提条件!$C$23,ROUND(前提条件!$C$21*(1+前提条件!$C$22)^18,0)) -> 62 | V8: =MIN(前提条件!$C$23,ROUND(前提条件!$C$21*(1+前提条件!$C$22)^19,0)) -> 71 | W8: =MIN(前提条件!$C$23,ROUND(前提条件!$C$21*(1+前提条件!$C$22)^20,0)) -> 82 | X8: =MIN(前提条件!$C$23,ROUND(前提条件!$C$21*(1+前提条件!$C$22)^21,0)) -> 94 | Y8: =MIN(前提条件!$C$23,ROUND(前提条件!$C$21*(1+前提条件!$C$22)^22,0)) -> 108 | Z8: =MIN(前提条件!$C$23,ROUND(前提条件!$C$21*(1+前提条件!$C$22)^23,0)) -> 120 | AA8: =MIN(前提条件!$C$23,ROUND(前提条件!$C$21*(1+前提条件!$C$22)^24,0)) -> 120 | AB8: =MIN(前提条件!$C$23,ROUND(前提条件!$C$21*(1+前提条件!$C$22)^25,0)) -> 120 | AC8: =MIN(前提条件!$C$23,ROUND(前提条件!$C$21*(1+前提条件!$C$22)^26,0)) -> 120 | AD8: =MIN(前提条件!$C$23,ROUND(前提条件!$C$21*(1+前提条件!$C$22)^27,0)) -> 120 | AE8: =MIN(前提条件!$C$23,ROUND(前提条件!$C$21*(1+前提条件!$C$22)^28,0)) -> 120 | AF8: =MIN(前提条件!$C$23,ROUND(前提条件!$C$21*(1+前提条件!$C$22)^29,0)) -> 120 | AG8: =MIN(前提条件!$C$23,ROUND(前提条件!$C$21*(1+前提条件!$C$22)^30,0)) -> 120 | AH8: =MIN(前提条件!$C$23,ROUND(前提条件!$C$21*(1+前提条件!$C$22)^31,0)) -> 120 | AI8: =MIN(前提条件!$C$23,ROUND(前提条件!$C$21*(1+前提条件!$C$22)^32,0)) -> 120 | AJ8: =MIN(前提条件!$C$23,ROUND(前提条件!$C$21*(1+前提条件!$C$22)^33,0)) -> 120 | AK8: =MIN(前提条件!$C$23,ROUND(前提条件!$C$21*(1+前提条件!$C$22)^34,0)) -> 120 | AL8: =MIN(前提条件!$C$23,ROUND(前提条件!$C$21*(1+前提条件!$C$22)^35,0)) -> 120
B9: 解約 | C9: =-ROUND(C7*前提条件!$C$24,0) -> 0 | D9: =-ROUND(D7*前提条件!$C$24,0) -> 0 | E9: =-ROUND(E7*前提条件!$C$24,0) -> 0 | F9: =-ROUND(F7*前提条件!$C$24,0) -> -1 | G9: =-ROUND(G7*前提条件!$C$24,0) -> -1 | H9: =-ROUND(H7*前提条件!$C$24,0) -> -1 | I9: =-ROUND(I7*前提条件!$C$24,0) -> -1 | J9: =-ROUND(J7*前提条件!$C$24,0) -> -2 | ... AL9: =-ROUND(AL7*前提条件!$C$24,0) -> -51
B10: 期末店舗数 | C10: =C7+C8+C9 -> 5 | D10: =D7+D8+D9 -> 11 | E10: =E7+E8+E9 -> 18 | F10: =F7+F8+F9 -> 25 | G10: =G7+G8+G9 -> 33 | H10: =H7+H8+H9 -> 42 | I10: =I7+I8+I9 -> 53 | J10: =J7+J8+J9 -> 64 | ... AL10: =AL7+AL8+AL9 -> 1765
B11: 平均店舗数 | C11: =(C7+C10)/2 -> 2.5 | D11: =(D7+D10)/2 -> 8 | E11: =(E7+E10)/2 -> 14.5 | F11: =(F7+F10)/2 -> 21.5 | G11: =(G7+G10)/2 -> 29 | H11: =(H7+H10)/2 -> 37.5 | I11: =(I7+I10)/2 -> 47.5 | J11: =(J7+J10)/2 -> 58.5 | ... AL11: =(AL7+AL10)/2 -> 1730.5
B13: 損益
B14: 売上（税込） | C14: =C11*単位経済!$E$7 -> 5710.5 | D14: =D11*単位経済!$E$7 -> 18273.6 | E14: =E11*単位経済!$E$7 -> 33120.9 | F14: =F11*単位経済!$E$7 -> 49110.3 | G14: =G11*単位経済!$E$7 -> 66241.8 | H14: =H11*単位経済!$E$7 -> 85657.5 | I14: =I11*単位経済!$E$7 -> 108499.5 | J14: =J11*単位経済!$E$7 -> 133625.7 | ... AL14: =AL11*単位経済!$E$7 -> 3952808.1
B15: 消費税 | C15: =-C14*前提条件!$C$16/(1+前提条件!$C$16) -> -519.13636 | D15: =-D14*前提条件!$C$16/(1+前提条件!$C$16) -> -1661.2364 | E15: =-E14*前提条件!$C$16/(1+前提条件!$C$16) -> -3010.9909 | F15: =-F14*前提条件!$C$16/(1+前提条件!$C$16) -> -4464.5727 | G15: =-G14*前提条件!$C$16/(1+前提条件!$C$16) -> -6021.9818 | H15: =-H14*前提条件!$C$16/(1+前提条件!$C$16) -> -7787.0455 | I15: =-I14*前提条件!$C$16/(1+前提条件!$C$16) -> -9863.5909 | J15: =-J14*前提条件!$C$16/(1+前提条件!$C$16) -> -12147.791 | ... AL15: =-AL14*前提条件!$C$16/(1+前提条件!$C$16) -> -359346.19
B16: Stripe 手数料 | C16: =-C14*前提条件!$C$17 -> -205.578 | D16: =-D14*前提条件!$C$17 -> -657.8496 | E16: =-E14*前提条件!$C$17 -> -1192.3524 | F16: =-F14*前提条件!$C$17 -> -1767.9708 | G16: =-G14*前提条件!$C$17 -> -2384.7048 | H16: =-H14*前提条件!$C$17 -> -3083.67 | I16: =-I14*前提条件!$C$17 -> -3905.982 | J16: =-J14*前提条件!$C$17 -> -4810.5252 | ... AL16: =-AL14*前提条件!$C$17 -> -142301.09
B17: 純売上 | C17: =C14+C15+C16 -> 4985.7856 | D17: =D14+D15+D16 -> 15954.514 | E17: =E14+E15+E16 -> 28917.557 | F17: =F14+F15+F16 -> 42877.756 | G17: =G14+G15+G16 -> 57835.113 | H17: =H14+H15+H16 -> 74786.785 | I17: =I14+I15+I16 -> 94729.927 | J17: =J14+J15+J16 -> 116667.38 | ... AL17: =AL14+AL15+AL16 -> 3451160.8
B18: 創作者分配 | C18: =-C17*前提条件!$C$18 -> -2243.6035 | D18: =-D17*前提条件!$C$18 -> -7179.5313 | E18: =-E17*前提条件!$C$18 -> -13012.901 | F18: =-F17*前提条件!$C$18 -> -19294.99 | G18: =-G17*前提条件!$C$18 -> -26025.801 | H18: =-H17*前提条件!$C$18 -> -33654.053 | I18: =-I17*前提条件!$C$18 -> -42628.467 | J18: =-J17*前提条件!$C$18 -> -52500.323 | ... AL18: =-AL17*前提条件!$C$18 -> -1553022.4
B19: 貢献利益 | C19: =C17+C18 -> 2742.1821 | D19: =D17+D18 -> 8774.9827 | E19: =E17+E18 -> 15904.656 | F19: =F17+F18 -> 23582.766 | G19: =G17+G18 -> 31809.312 | H19: =H17+H18 -> 41132.732 | I19: =I17+I18 -> 52101.46 | J19: =J17+J18 -> 64167.061 | ... AL19: =AL17+AL18 -> 1898138.4
B21: 費用
B22: カタログ曲数 | C22: =前提条件!$C$45+前提条件!$C$46*1 -> 5000 | D22: =前提条件!$C$45+前提条件!$C$46*2 -> 7000 | E22: =前提条件!$C$45+前提条件!$C$46*3 -> 9000 | F22: =前提条件!$C$45+前提条件!$C$46*4 -> 11000 | G22: =前提条件!$C$45+前提条件!$C$46*5 -> 13000 | H22: =前提条件!$C$45+前提条件!$C$46*6 -> 15000 | I22: =前提条件!$C$45+前提条件!$C$46*7 -> 17000 | J22: =前提条件!$C$45+前提条件!$C$46*8 -> 19000 | K22: =前提条件!$C$45+前提条件!$C$46*9 -> 21000 | L22: =前提条件!$C$45+前提条件!$C$46*10 -> 23000 | M22: =前提条件!$C$45+前提条件!$C$46*11 -> 25000 | N22: =前提条件!$C$45+前提条件!$C$46*12 -> 27000 | O22: =前提条件!$C$45+前提条件!$C$46*13 -> 29000 | P22: =前提条件!$C$45+前提条件!$C$46*14 -> 31000 | Q22: =前提条件!$C$45+前提条件!$C$46*15 -> 33000 | R22: =前提条件!$C$45+前提条件!$C$46*16 -> 35000 | S22: =前提条件!$C$45+前提条件!$C$46*17 -> 37000 | T22: =前提条件!$C$45+前提条件!$C$46*18 -> 39000 | U22: =前提条件!$C$45+前提条件!$C$46*19 -> 41000 | V22: =前提条件!$C$45+前提条件!$C$46*20 -> 43000 | W22: =前提条件!$C$45+前提条件!$C$46*21 -> 45000 | X22: =前提条件!$C$45+前提条件!$C$46*22 -> 47000 | Y22: =前提条件!$C$45+前提条件!$C$46*23 -> 49000 | Z22: =前提条件!$C$45+前提条件!$C$46*24 -> 51000 | AA22: =前提条件!$C$45+前提条件!$C$46*25 -> 53000 | AB22: =前提条件!$C$45+前提条件!$C$46*26 -> 55000 | AC22: =前提条件!$C$45+前提条件!$C$46*27 -> 57000 | AD22: =前提条件!$C$45+前提条件!$C$46*28 -> 59000 | AE22: =前提条件!$C$45+前提条件!$C$46*29 -> 61000 | AF22: =前提条件!$C$45+前提条件!$C$46*30 -> 63000 | AG22: =前提条件!$C$45+前提条件!$C$46*31 -> 65000 | AH22: =前提条件!$C$45+前提条件!$C$46*32 -> 67000 | AI22: =前提条件!$C$45+前提条件!$C$46*33 -> 69000 | AJ22: =前提条件!$C$45+前提条件!$C$46*34 -> 71000 | AK22: =前提条件!$C$45+前提条件!$C$46*35 -> 73000 | AL22: =前提条件!$C$45+前提条件!$C$46*36 -> 75000
B23: ストレージ（GB） | C23: =C22*前提条件!$C$44 -> 210 | D23: =D22*前提条件!$C$44 -> 294 | E23: =E22*前提条件!$C$44 -> 378 | F23: =F22*前提条件!$C$44 -> 462 | G23: =G22*前提条件!$C$44 -> 546 | H23: =H22*前提条件!$C$44 -> 630 | I23: =I22*前提条件!$C$44 -> 714 | J23: =J22*前提条件!$C$44 -> 798 | ... AL23: =AL22*前提条件!$C$44 -> 3150
B24: インフラ費 | C24: =-(C23*前提条件!$C$43+前提条件!$C$47+前提条件!$C$46/1000*前提条件!$C$48)*前提条件!$C$42 -> -24668.25 | D24: =-(D23*前提条件!$C$43+前提条件!$C$47+前提条件!$C$46/1000*前提条件!$C$48)*前提条件!$C$42 -> -24863.55 | E24: =-(E23*前提条件!$C$43+前提条件!$C$47+前提条件!$C$46/1000*前提条件!$C$48)*前提条件!$C$42 -> -25058.85 | F24: =-(F23*前提条件!$C$43+前提条件!$C$47+前提条件!$C$46/1000*前提条件!$C$48)*前提条件!$C$42 -> -25254.15 | G24: =-(G23*前提条件!$C$43+前提条件!$C$47+前提条件!$C$46/1000*前提条件!$C$48)*前提条件!$C$42 -> -25449.45 | H24: =-(H23*前提条件!$C$43+前提条件!$C$47+前提条件!$C$46/1000*前提条件!$C$48)*前提条件!$C$42 -> -25644.75 | I24: =-(I23*前提条件!$C$43+前提条件!$C$47+前提条件!$C$46/1000*前提条件!$C$48)*前提条件!$C$42 -> -25840.05 | J24: =-(J23*前提条件!$C$43+前提条件!$C$47+前提条件!$C$46/1000*前提条件!$C$48)*前提条件!$C$42 -> -26035.35 | ... AL24: =-(AL23*前提条件!$C$43+前提条件!$C$47+前提条件!$C$46/1000*前提条件!$C$48)*前提条件!$C$42 -> -31503.75
B25: 人件費 | C25: =-(前提条件!$C$30*前提条件!$C$31+前提条件!$C$32*前提条件!$C$33+前提条件!$C$34*前提条件!$C$35+前提条件!$C$36*前提条件!$C$37) -> -2400000 | D25: =-(前提条件!$C$30*前提条件!$C$31+前提条件!$C$32*前提条件!$C$33+前提条件!$C$34*前提条件!$C$35+前提条件!$C$36*前提条件!$C$37) -> -2400000 | E25: =-(前提条件!$C$30*前提条件!$C$31+前提条件!$C$32*前提条件!$C$33+前提条件!$C$34*前提条件!$C$35+前提条件!$C$36*前提条件!$C$37) -> -2400000 | F25: =-(前提条件!$C$30*前提条件!$C$31+前提条件!$C$32*前提条件!$C$33+前提条件!$C$34*前提条件!$C$35+前提条件!$C$36*前提条件!$C$37) -> -2400000 | G25: =-(前提条件!$C$30*前提条件!$C$31+前提条件!$C$32*前提条件!$C$33+前提条件!$C$34*前提条件!$C$35+前提条件!$C$36*前提条件!$C$37) -> -2400000 | H25: =-(前提条件!$C$30*前提条件!$C$31+前提条件!$C$32*前提条件!$C$33+前提条件!$C$34*前提条件!$C$35+前提条件!$C$36*前提条件!$C$37) -> -2400000 | I25: =-(前提条件!$C$30*前提条件!$C$31+前提条件!$C$32*前提条件!$C$33+前提条件!$C$34*前提条件!$C$35+前提条件!$C$36*前提条件!$C$37) -> -2400000 | J25: =-(前提条件!$C$30*前提条件!$C$31+前提条件!$C$32*前提条件!$C$33+前提条件!$C$34*前提条件!$C$35+前提条件!$C$36*前提条件!$C$37) -> -2400000 | ... AL25: =-(前提条件!$C$30*前提条件!$C$31+前提条件!$C$32*前提条件!$C$33+前提条件!$C$34*前提条件!$C$35+前提条件!$C$36*前提条件!$C$37) -> -2400000
B26: その他固定費・法務 | C26: =-(前提条件!$C$38+前提条件!$C$39) -> -250000 | D26: =-(前提条件!$C$38+前提条件!$C$39) -> -250000 | E26: =-(前提条件!$C$38+前提条件!$C$39) -> -250000 | F26: =-(前提条件!$C$38+前提条件!$C$39) -> -250000 | G26: =-(前提条件!$C$38+前提条件!$C$39) -> -250000 | H26: =-(前提条件!$C$38+前提条件!$C$39) -> -250000 | I26: =-(前提条件!$C$38+前提条件!$C$39) -> -250000 | J26: =-(前提条件!$C$38+前提条件!$C$39) -> -250000 | ... AL26: =-(前提条件!$C$38+前提条件!$C$39) -> -250000
B27: 顧客獲得費 | C27: =-C8*前提条件!$C$27 -> -100000 | D27: =-D8*前提条件!$C$27 -> -120000 | E27: =-E8*前提条件!$C$27 -> -140000 | F27: =-F8*前提条件!$C$27 -> -160000 | G27: =-G8*前提条件!$C$27 -> -180000 | H27: =-H8*前提条件!$C$27 -> -200000 | I27: =-I8*前提条件!$C$27 -> -240000 | J27: =-J8*前提条件!$C$27 -> -260000 | ... AL27: =-AL8*前提条件!$C$27 -> -2400000
B28: 費用合計 | C28: =SUM(C24:C27) -> -2774668.2 | D28: =SUM(D24:D27) -> -2794863.5 | E28: =SUM(E24:E27) -> -2815058.9 | F28: =SUM(F24:F27) -> -2835254.1 | G28: =SUM(G24:G27) -> -2855449.5 | H28: =SUM(H24:H27) -> -2875644.8 | I28: =SUM(I24:I27) -> -2915840 | J28: =SUM(J24:J27) -> -2936035.4 | ... AL28: =SUM(AL24:AL27) -> -5081503.8
B30: 営業利益 | C30: =C19+C28 -> -2771926.1 | D30: =D19+D28 -> -2786088.6 | E30: =E19+E28 -> -2799154.2 | F30: =F19+F28 -> -2811671.4 | G30: =G19+G28 -> -2823640.1 | H30: =H19+H28 -> -2834512 | I30: =I19+I28 -> -2863738.6 | J30: =J19+J28 -> -2871868.3 | ... AL30: =AL19+AL28 -> -3183365.3
B31: 累積営業利益 | C31: =C30 -> -2771926.1 | D31: =C31+D30 -> -5558014.6 | E31: =D31+E30 -> -8357168.8 | F31: =E31+F30 -> -11168840 | G31: =F31+G30 -> -13992480 | H31: =G31+H30 -> -16826992 | I31: =H31+I30 -> -19690731 | J31: =I31+J30 -> -22562599 | K31: =J31+K30 -> -25461500 | ... AL31: =AK31+AL30 -> -1.208916e+08
B32: MRR（税込） | C32: =C10*単位経済!$E$7 -> 11421 | D32: =D10*単位経済!$E$7 -> 25126.2 | E32: =E10*単位経済!$E$7 -> 41115.6 | F32: =F10*単位経済!$E$7 -> 57105 | G32: =G10*単位経済!$E$7 -> 75378.6 | H32: =H10*単位経済!$E$7 -> 95936.4 | I32: =I10*単位経済!$E$7 -> 121062.6 | J32: =J10*単位経済!$E$7 -> 146188.8 | ... AL32: =AL10*単位経済!$E$7 -> 4031613
B33: ARR（税込・年換算） | C33: =C32*12 -> 137052 | D33: =D32*12 -> 301514.4 | E33: =E32*12 -> 493387.2 | F33: =F32*12 -> 685260 | G33: =G32*12 -> 904543.2 | H33: =H32*12 -> 1151236.8 | I33: =I32*12 -> 1452751.2 | J33: =J32*12 -> 1754265.6 | ... AL33: =AL32*12 -> 48379356
B36: サマリー
B37: 36ヶ月後の店舗数 | C37: =AL10 -> 1765
B38: 36ヶ月後の MRR（税込） | C38: =AL32 -> 4031613
B39: 36ヶ月後の ARR（税込） | C39: =AL33 -> 48379356
B40: 単月黒字化する月 | C40: =IFERROR(MATCH(TRUE(),INDEX(C30:AL30>0,0),0),"36ヶ月内に達成せず") -> 36ヶ月内に達成せず
B41: 累積黒字化する月 | C41: =IFERROR(MATCH(TRUE(),INDEX(C31:AL31>0,0),0),"36ヶ月内に達成せず") -> 36ヶ月内に達成せず
B42: 累積赤字の最大額 | C42: =MIN(C31:AL31) -> -1.208916e+08
B43: 「累積赤字の最大額」が必要な調達額の目安（運転資本を除く）。

Sheet 損益分岐点
B2: 損益分岐点と感応度分析
B3: 何店舗で黒字化するか、そして前提が変わると答えがどう動くか。
B5: 1. 月次固定費
B6: 人件費 | C6: =前提条件!$C$30*前提条件!$C$31+前提条件!$C$32*前提条件!$C$33+前提条件!$C$34*前提条件!$C$35+前提条件!$C$36*前提条件!$C$37 -> 2400000
B7: その他固定費・法務 | C7: =前提条件!$C$38+前提条件!$C$39 -> 250000
B8: 固定インフラ費 | C8: =前提条件!$C$47*前提条件!$C$42 -> 21700
B9: 固定費合計（月） | C9: =SUM(C6:C8) -> 2671700 | I9: ストレージ・変換費は曲数に比例するため、ここでは固定費に含めない。
B11: 2. 損益分岐点
B12: 1 店舗あたり貢献利益（月） | C12: =単位経済!$E$12 -> 1096.8728 | I12: 単位経済シートより
B13: 損益分岐点（店舗数） | C13: =ROUNDUP(C9/C12,0) -> 2436 | I13: この店舗数を超えると単月黒字（顧客獲得費を除く）。
B14: 同・獲得費を含む場合 | C14: =ROUNDUP((C9+前提条件!$C$23*前提条件!$C$27*0.5)/C12,0) -> 3530 | I14: 月次新規獲得を上限の 50% と仮定した場合の獲得費を上乗せ。
B16: 3. 感応度：損益分岐点の店舗数
B17: 行 = Standard 月額（税込） / 列 = 創作者分配プール率
B18: 月額 ＼ 分配率 | C18: 0.3 | D18: 0.35 | E18: 0.4 | F18: 0.45 | G18: 0.5
B19: 1480 | C19: =ROUNDUP($C$9/(($B19*(1-前提条件!$C$10*前提条件!$C$9)/(1+前提条件!$C$16)-$B19*(1-前提条件!$C$10*前提条件!$C$9)*前提条件!$C$17)*(1-C$18)),0) -> 3143 | D19: =ROUNDUP($C$9/(($B19*(1-前提条件!$C$10*前提条件!$C$9)/(1+前提条件!$C$16)-$B19*(1-前提条件!$C$10*前提条件!$C$9)*前提条件!$C$17)*(1-D$18)),0) -> 3384 | E19: =ROUNDUP($C$9/(($B19*(1-前提条件!$C$10*前提条件!$C$9)/(1+前提条件!$C$16)-$B19*(1-前提条件!$C$10*前提条件!$C$9)*前提条件!$C$17)*(1-E$18)),0) -> 3666 | F19: =ROUNDUP($C$9/(($B19*(1-前提条件!$C$10*前提条件!$C$9)/(1+前提条件!$C$16)-$B19*(1-前提条件!$C$10*前提条件!$C$9)*前提条件!$C$17)*(1-F$18)),0) -> 4000 | G19: =ROUNDUP($C$9/(($B19*(1-前提条件!$C$10*前提条件!$C$9)/(1+前提条件!$C$16)-$B19*(1-前提条件!$C$10*前提条件!$C$9)*前提条件!$C$17)*(1-G$18)),0) -> 4400
B20: 1980 | C20: =ROUNDUP($C$9/(($B20*(1-前提条件!$C$10*前提条件!$C$9)/(1+前提条件!$C$16)-$B20*(1-前提条件!$C$10*前提条件!$C$9)*前提条件!$C$17)*(1-C$18)),0) -> 2349 | D20: =ROUNDUP($C$9/(($B20*(1-前提条件!$C$10*前提条件!$C$9)/(1+前提条件!$C$16)-$B20*(1-前提条件!$C$10*前提条件!$C$9)*前提条件!$C$17)*(1-D$18)),0) -> 2530 | E20: =ROUNDUP($C$9/(($B20*(1-前提条件!$C$10*前提条件!$C$9)/(1+前提条件!$C$16)-$B20*(1-前提条件!$C$10*前提条件!$C$9)*前提条件!$C$17)*(1-E$18)),0) -> 2741 | F20: =ROUNDUP($C$9/(($B20*(1-前提条件!$C$10*前提条件!$C$9)/(1+前提条件!$C$16)-$B20*(1-前提条件!$C$10*前提条件!$C$9)*前提条件!$C$17)*(1-F$18)),0) -> 2990 | G20: =ROUNDUP($C$9/(($B20*(1-前提条件!$C$10*前提条件!$C$9)/(1+前提条件!$C$16)-$B20*(1-前提条件!$C$10*前提条件!$C$9)*前提条件!$C$17)*(1-G$18)),0) -> 3289
B21: 2480 | C21: =ROUNDUP($C$9/(($B21*(1-前提条件!$C$10*前提条件!$C$9)/(1+前提条件!$C$16)-$B21*(1-前提条件!$C$10*前提条件!$C$9)*前提条件!$C$17)*(1-C$18)),0) -> 1876 | D21: =ROUNDUP($C$9/(($B21*(1-前提条件!$C$10*前提条件!$C$9)/(1+前提条件!$C$16)-$B21*(1-前提条件!$C$10*前提条件!$C$9)*前提条件!$C$17)*(1-D$18)),0) -> 2020 | E21: =ROUNDUP($C$9/(($B21*(1-前提条件!$C$10*前提条件!$C$9)/(1+前提条件!$C$16)-$B21*(1-前提条件!$C$10*前提条件!$C$9)*前提条件!$C$17)*(1-E$18)),0) -> 2188 | F21: =ROUNDUP($C$9/(($B21*(1-前提条件!$C$10*前提条件!$C$9)/(1+前提条件!$C$16)-$B21*(1-前提条件!$C$10*前提条件!$C$9)*前提条件!$C$17)*(1-F$18)),0) -> 2387 | G21: =ROUNDUP($C$9/(($B21*(1-前提条件!$C$10*前提条件!$C$9)/(1+前提条件!$C$16)-$B21*(1-前提条件!$C$10*前提条件!$C$9)*前提条件!$C$17)*(1-G$18)),0) -> 2626
B22: 2980 | C22: =ROUNDUP($C$9/(($B22*(1-前提条件!$C$10*前提条件!$C$9)/(1+前提条件!$C$16)-$B22*(1-前提条件!$C$10*前提条件!$C$9)*前提条件!$C$17)*(1-C$18)),0) -> 1561 | D22: =ROUNDUP($C$9/(($B22*(1-前提条件!$C$10*前提条件!$C$9)/(1+前提条件!$C$16)-$B22*(1-前提条件!$C$10*前提条件!$C$9)*前提条件!$C$17)*(1-D$18)),0) -> 1681 | E22: =ROUNDUP($C$9/(($B22*(1-前提条件!$C$10*前提条件!$C$9)/(1+前提条件!$C$16)-$B22*(1-前提条件!$C$10*前提条件!$C$9)*前提条件!$C$17)*(1-E$18)),0) -> 1821 | F22: =ROUNDUP($C$9/(($B22*(1-前提条件!$C$10*前提条件!$C$9)/(1+前提条件!$C$16)-$B22*(1-前提条件!$C$10*前提条件!$C$9)*前提条件!$C$17)*(1-F$18)),0) -> 1987 | G22: =ROUNDUP($C$9/(($B22*(1-前提条件!$C$10*前提条件!$C$9)/(1+前提条件!$C$16)-$B22*(1-前提条件!$C$10*前提条件!$C$9)*前提条件!$C$17)*(1-G$18)),0) -> 2185
B23: 3480 | C23: =ROUNDUP($C$9/(($B23*(1-前提条件!$C$10*前提条件!$C$9)/(1+前提条件!$C$16)-$B23*(1-前提条件!$C$10*前提条件!$C$9)*前提条件!$C$17)*(1-C$18)),0) -> 1337 | D23: =ROUNDUP($C$9/(($B23*(1-前提条件!$C$10*前提条件!$C$9)/(1+前提条件!$C$16)-$B23*(1-前提条件!$C$10*前提条件!$C$9)*前提条件!$C$17)*(1-D$18)),0) -> 1440 | E23: =ROUNDUP($C$9/(($B23*(1-前提条件!$C$10*前提条件!$C$9)/(1+前提条件!$C$16)-$B23*(1-前提条件!$C$10*前提条件!$C$9)*前提条件!$C$17)*(1-E$18)),0) -> 1560 | F23: =ROUNDUP($C$9/(($B23*(1-前提条件!$C$10*前提条件!$C$9)/(1+前提条件!$C$16)-$B23*(1-前提条件!$C$10*前提条件!$C$9)*前提条件!$C$17)*(1-F$18)),0) -> 1701 | G23: =ROUNDUP($C$9/(($B23*(1-前提条件!$C$10*前提条件!$C$9)/(1+前提条件!$C$16)-$B23*(1-前提条件!$C$10*前提条件!$C$9)*前提条件!$C$17)*(1-G$18)),0) -> 1871
B24: ※ Standard 単価のみを動かした場合。Custom 比率は前提条件のまま。
B26: 4. 感応度：LTV / CAC
B27: 行 = 月次解約率 / 列 = CAC。3.0x 以上が健全水準。
B28: 解約率 ＼ CAC | C28: 10000 | D28: 15000 | E28: 20000 | F28: 30000 | G28: 40000
B29: 0.02 | C29: =(単位経済!$E$12/$B29)/C$28 -> 5.4843642 | D29: =(単位経済!$E$12/$B29)/D$28 -> 3.6562428 | E29: =(単位経済!$E$12/$B29)/E$28 -> 2.7421821 | F29: =(単位経済!$E$12/$B29)/F$28 -> 1.8281214 | G29: =(単位経済!$E$12/$B29)/G$28 -> 1.371091
B30: 0.025 | C30: =(単位経済!$E$12/$B30)/C$28 -> 4.3874914 | D30: =(単位経済!$E$12/$B30)/D$28 -> 2.9249942 | E30: =(単位経済!$E$12/$B30)/E$28 -> 2.1937457 | F30: =(単位経済!$E$12/$B30)/F$28 -> 1.4624971 | G30: =(単位経済!$E$12/$B30)/G$28 -> 1.0968728
B31: 0.03 | C31: =(単位経済!$E$12/$B31)/C$28 -> 3.6562428 | D31: =(単位経済!$E$12/$B31)/D$28 -> 2.4374952 | E31: =(単位経済!$E$12/$B31)/E$28 -> 1.8281214 | F31: =(単位経済!$E$12/$B31)/F$28 -> 1.2187476 | G31: =(単位経済!$E$12/$B31)/G$28 -> 0.9140607
B32: 0.04 | C32: =(単位経済!$E$12/$B32)/C$28 -> 2.7421821 | D32: =(単位経済!$E$12/$B32)/D$28 -> 1.8281214 | E32: =(単位経済!$E$12/$B32)/E$28 -> 1.371091 | F32: =(単位経済!$E$12/$B32)/F$28 -> 0.9140607 | G32: =(単位経済!$E$12/$B32)/G$28 -> 0.68554552
B33: 0.05 | C33: =(単位経済!$E$12/$B33)/C$28 -> 2.1937457 | D33: =(単位経済!$E$12/$B33)/D$28 -> 1.4624971 | E33: =(単位経済!$E$12/$B33)/E$28 -> 1.0968728 | F33: =(単位経済!$E$12/$B33)/F$28 -> 0.73124856 | G33: =(単位経済!$E$12/$B33)/G$28 -> 0.54843642
B34: ※ 貢献利益は現在の前提値を使用。価格を変えた場合は上の表と併せて読むこと。
B36: 5. 人員体制別の損益分岐点
B37: 体制 | C37: 月次固定費 | D37: 損益分岐点（店舗） | E37: 到達までの目安
B38: 創業者 2 名のみ | C38: 700000 | D38: =ROUNDUP(C38/$C$12,0) -> 639 | E38: 自己資金・副業ペース
B39: 創業者 2 名 ＋ 審査 1 名 | C39: 1100000 | D39: =ROUNDUP(C39/$C$12,0) -> 1003 | E39: Phase 1 想定
B40: 小規模チーム（4 名） | C40: 1900000 | D40: =ROUNDUP(C40/$C$12,0) -> 1733 | E40: Phase 2 想定
B41: 標準チーム（前提条件どおり） | C41: =$C$9 -> 2671700 | D41: =ROUNDUP(C41/$C$12,0) -> 2436 | E41: Phase 2〜3 想定
B42: 拡大チーム（8 名） | C42: 4500000 | D42: =ROUNDUP(C42/$C$12,0) -> 4103 | E42: Phase 3 想定
B44: 読み方
B45: ・貢献利益率が 50% 前後にとどまるため、損益分岐点の店舗数は直感より大きくなる。
B46: ・分配プール率を初期は低めに設定し、規模拡大後に引き上げる設計も検討に値する（ただし創作者への説明が必要）。
B47: ・価格を ¥1,980 → ¥2,980 に上げた場合の効果は、分配率を 45% → 30% に下げる効果とほぼ同等。上の表で比較できる。

Sheet 競合比較
B2: 競合比較（2026年8月 調査時点）
B3: 3年総額 = 月額 × 36 ＋ 初期費用。店舗が実際に比較するのはこの数字。
B5: サービス | C5: 月額（税込） | D5: 初期費用 | E5: 3年総額 | F5: 対 Kanade 差額 | G5: 権利処理 | H5: 備考
B6: Kanade Standard | C6: =前提条件!$C$7 -> 1980 | D6: 0 | E6: =C6*36+D6 -> 71280 | F6: =E6-$E$6 -> 0 | G6: 管理外 | H6: 自社。AI 生成オリジナルのみ
B7: Kanade Custom | C7: =前提条件!$C$8 -> 4980 | D7: 0 | E7: =C7*36+D7 -> 179280 | F7: =E7-$E$6 -> 108000 | G7: 管理外 | H7: 店舗専属カタログ
B8: USEN MUSIC | C8: 6600 | D8: 22000 | E8: =C8*36+D8 -> 259600 | F8: =E8-$E$6 -> 188320 | G8: 包括契約込 | H8: 初期費用はキャンペーン価格。通常 ¥33,000
B9: OTORAKU | C9: 3278 | D9: 3300 | E9: =C9*36+D9 -> 121308 | F9: =E9-$E$6 -> 50028 | G9: 包括契約込 | H9: USEN 運営。950万曲以上
B10: FaRao PRO | C10: 3300 | D10: 0 | E10: =C10*36+D10 -> 118800 | F10: =E10-$E$6 -> 47520 | G10: 包括契約込 | H10: 初期費用は要確認
B11: モンスター・チャンネル | C11: 2068 | D11: 0 | E11: =C11*36+D11 -> 74448 | F11: =E11-$E$6 -> 3168 | G11: 包括契約込 | H11: 2年プラン。月払いは ¥3,168
B12: Audiostock 店舗音楽 | C12: 2200 | D12: 0 | E12: =C12*36+D12 -> 79200 | F12: =E12-$E$6 -> 7920 | G12: 包括契約込 | H12: 月間 5,000曲以上
B13: BGMC Station | C13: 1078 | D13: 0 | E13: =C13*36+D13 -> 38808 | F13: =E13-$E$6 -> -32472 | G13: 申請不要 | H13: 著作権フリー系。曲数が限られる
B14: BGM House | C14: 1089 | D14: 0 | E14: =C14*36+D14 -> 39204 | F14: =E14-$E$6 -> -32076 | G14: 著作権フリー | H14: オリジナル中心
B15: らくネット | C15: 690 | D15: 4000 | E15: =C15*36+D15 -> 28840 | F15: =E15-$E$6 -> -42440 | G15: 申請不要 | H15: 約30ch
B16: Simple BGM | C16: 550 | D16: 0 | E16: =C16*36+D16 -> 19800 | F16: =E16-$E$6 -> -51480 | G16: 申請不要 | H16: 最安値帯。10万曲以上
B17: ※ 月額は各社公表値または代理店公開情報。契約期間・店舗規模により変動する。
B18: ※ USEN の月額は公式サイトでは非公開。代理店公開情報による。
B20: レコード演奏・伝達権 施行後の想定
B21: 2026年6月24日公布、施行は3年以内（最遅 2029年6月）。商業用レコードを再生する店舗に新たな負担が生じる。
B22: 想定追加負担（月額） | C22: 500 | H22: 指定団体の使用料規程は未公表。JASRAC 相当額を仮置きした推測値。
B23: 包括契約型サービスの実質月額 | C23: =E8/36+C22 -> 7711.1111 | H23: USEN の3年総額を月割りし、想定追加負担を加算した値。
B24: Kanade Standard の実質月額 | C24: =前提条件!$C$7 -> 1980 | H24: オリジナル楽曲のみのため追加負担なし（要弁護士確認）。
B25: 価格差の拡大 | C25: =C23-C24 -> 5731.1111
B27: 注意
B28: ・上の追加負担 ¥500 は仮置き。指定団体の使用料規程が公表され次第、必ず実額に置き換えること。
B29: ・指定団体が包括徴収方式を採る場合、管理外楽曲のみを再生する店舗にも一旦請求が及ぶ可能性がある。
B30: ・その場合でも「再生ログ」と「管理外証明書」による免除申請の支援が差別化要因として残る（設計書 10 の R-02）。
